Workbook
Name W_FIAB: Supuestos!$B$7
Name W_PRECIO: Supuestos!$B$8
Name W_ESTADO: Supuestos!$B$9
Name W_ESTETICA: Supuestos!$B$10
Name W_SEGVIAL: Supuestos!$B$11
Name W_SEGURIDAD: Supuestos!$B$12
Name W_USO: Supuestos!$B$13
Name W_KMEDAD: Supuestos!$B$14
Name W_REVENTA: Supuestos!$B$15
Name W_COLOR: Supuestos!$B$16
Name W_SUMA: Supuestos!$B$17
Name ANIO_ACTUAL: Supuestos!$B$21
Name ANIO_MIN: Supuestos!$B$22
Name KM_MAX: Supuestos!$B$23
Name PRECIO_MAX: Supuestos!$B$24
Name TOTAL_MAX: Supuestos!$B$25
Name TECHO: Supuestos!$B$26
Name PEN_100: Supuestos!$B$27
Name SEG_ANIO: Supuestos!$B$28
Name SEG_KM: Supuestos!$B$29
Name MIN_N: Supuestos!$B$30
Name PRECIO_PEND: Supuestos!$B$31
Name KM_TOPE_DESDE: Supuestos!$B$32
Name KM_TOPE_PTS: Supuestos!$B$33
Name ROB_PEN: Supuestos!$B$34
Name KMA_IDEAL_MAX: Supuestos!$B$35
Name KMA_CERO: Supuestos!$B$36
Name KMA_SOSP: Supuestos!$B$37
Name KMA_PEN: Supuestos!$B$38
Name W_KMT: Supuestos!$B$39
Name W_KMA: Supuestos!$B$40
Name W_EDAD: Supuestos!$B$41
Name E_ITV: Supuestos!$B$42
Name E_LIBRO: Supuestos!$B$43
Name E_PROP: Supuestos!$B$44
Name E_CORREA: Supuestos!$B$45
Name E_FACT: Supuestos!$B$46
Name W_ET: Supuestos!$B$47
Name W_CONS: Supuestos!$B$48
Name W_SEG: Supuestos!$B$49
Name W_MANT: Supuestos!$B$50
Name NEUTRO: Supuestos!$B$51
Name SG_GAR: Supuestos!$B$52
Name SG_GAR_FULL: Supuestos!$B$53
Name SG_AMPL: Supuestos!$B$54
Name SG_KMC: Supuestos!$B$55
Name SG_REV: Supuestos!$B$56
Name SG_DEV: Supuestos!$B$57
Name SG_DEV_FULL: Supuestos!$B$58
Name SG_HIST: Supuestos!$B$59
Name SG_LEGAL_ON: Supuestos!$B$60
Name GAR_LEGAL: Supuestos!$B$61
Name SG_PART_PEN: Supuestos!$B$62
Name SV_W_NCAP: Supuestos!$B$63
Name SV_W_ESP: Supuestos!$B$64
Name RV_W_LIQ: Supuestos!$B$65
Name RV_N_FULL: Supuestos!$B$66
Name RV_W_DIAS: Supuestos!$B$67
Name RV_DIAS_FULL: Supuestos!$B$68
Name RV_DIAS_CERO: Supuestos!$B$69

Sheet Anuncios
A1: ID | B1: Plataforma | C1: URL | D1: Título | E1: Marca | F1: Modelo | G1: Motor (normalizado) | H1: Versión | I1: Cilindrada (cc) | J1: Potencia (CV) | K1: Combustible | L1: Segmento | M1: Año | N1: Km | O1: Precio (€) | P1: Cambio | Q1: Automático | R1: Vendedor | S1: Ubicación | T1: Publicado | U1: Nº fotos | V1: ITV en vigor | W1: Libro mantenimiento | X1: Correa/distrib. cambiada | Y1: Nº propietarios | Z1: Garantía | AA1: Km justificados | AB1: Garantía incluida (meses) | AC1: Garantía ampliable | AD1: Precio ampliación garantía (€) | AE1: Revisión (puntos) | AF1: Km certificados | AG1: Devolución (días) | AH1: Precio al contado (€) | AI1: Precio financiado (€) | AJ1: Precio anunciado solo financiando | AK1: Gastos de gestión del vendedor (€) | AL1: Gastos incluyen transferencia | AM1: Distancia a València (km) | AN1: Matrícula | AO1: 1.ª matriculación (anuncio) | AP1: Año 1.ª matric. | AQ1: Mes 1.ª matric. | AR1: Etiqueta DGT/anuncio | AS1: Fuente etiqueta | AT1: Año en URL/título distinto (a confirmar) | AU1: Etiqueta dudosa por año | AV1: Etiquetas posibles | AW1: Anuncio incoherente (etiqueta del anuncio) | AX1: Caja robotizada | AY1: Modelo de estetica.yaml admitido de particular | AZ1: Color (anuncio) | BA1: Color normalizado | BB1: Estética del modelo (1-5) | BC1: Entrada de estetica.yaml | BD1: Acabado alto/deportivo | BE1: Llantas (16+ / sí / chapa) | BF1: Faros xenón/LED | BG1: Cristales tintados | BH1: Correa con fecha o km | BI1: Facturas | BJ1: Neumáticos nuevos | BK1: Euro NCAP (estrellas) | BL1: ESP/ESC | BM1: Anuncios del modelo en el mercado | BN1: Días medianos hasta desaparecer | BO1: Ventas observadas del modelo | BP1: Mediana de mercado del segmento (€) | BQ1: N mercado | BR1: Nivel mediana mercado | BS1: Duplicados fusionados | BT1: Avisos | BU1: Descripción | BV1: Fuente (fichero /raw) | BW1: Edad (años) | BX1: Km/año | BY1: Seg. modelo | BZ1: Seg. modelo+año | CA1: Seg. modelo+año+km | CB1: N modelo | CC1: N modelo+año | CD1: N modelo+año+km | CE1: Mediana segmento (€) | CF1: Nivel mediana | CG1: Descuento vs mediana | CH1: Año frontera (1/0) | CI1: Año anterior frontera (1/0) | CJ1: AAAAMM para la regla | CK1: Etiqueta por regla | CL1: ETIQUETA | CM1: Etiqueta dudosa | CN1: Fiab. base modelo | CO1: Ajuste motor | CP1: Ajuste combustible | CQ1: Motor con fuente (nº entradas) | CR1: Fiab. base aplicada | CS1: P. Fiabilidad | CT1: Tope nota precio por km | CU1: P. Precio | CV1: P. km totales | CW1: P. km/año | CX1: P. edad | CY1: P. Km y edad | CZ1: Clave marca|motor | DA1: Distribución | DB1: P. Estado y mantenimiento | DC1: P. Etiqueta y ZBE | DD1: Consumo estimado l/100 km (aprox.) | DE1: P. consumo | DF1: Seguro estimado €/año (aprox.) | DG1: P. seguro | DH1: P. recambios marca | DI1: P. distribución | DJ1: P. mantenimiento | DK1: P. Coste uso | DL1: Garantía efectiva (meses) | DM1: P. Seguridad compra | DN1: P. Euro NCAP | DO1: P. ESP | DP1: P. Seguridad (NCAP + ESP) | DQ1: P. atributos | DR1: P. Estética | DS1: P. Color | DT1: P. liquidez | DU1: P. días de venta | DV1: P. Reventa y liquidez | DW1: Penalización carrocería (puntos) | DX1: PUNTUACIÓN | DY1: cc para ITP | DZ1: ITP (€) | EA1: Gastos vendedor en coste (€) | EB1: Tasa DGT (€) | EC1: Informe DGT (€) | ED1: COSTE TOTAL (€) | EE1: Coste 1er año con seguro (€) | EF1: Exceso sobre presupuesto = € a negociar | EG1: Penalización presupuesto (puntos) | EH1: Coste real estimado particular (€, informativo) | EI1: Presupuesto (sí / negociar / no) | EJ1: Puntuación redondeada (desempate) | EK1: Puesto
A2: ocasionplus:b9auzqaa | B2: ocasionplus | C2: https://www.ocasionplus.com/coches-segunda-mano/peugeot-207-14-confort-con-116183km-2008-b9auzqaa | D2: Peugeot 207 1.4 Confort (75 CV) | E2: Peugeot | F2: Peugeot 207 | G2: 1.4 | H2: Peugeot 207 1.4 Confort (75 CV) | I2: 1360 | J2: 75 | K2: gasolina | L2: utilitario | M2: 2008 | N2: 116183 | O2: 2900 | P2: manual | Q2: no | R2: profesional | S2: Valencia - Sagunto (Sagunto, 46500) | T2: 2026-10-27T00:00:00.000Z | U2: 25 | V2: sí | Y2: 0 | AC2: sí | AD2: 500 | AF2: sí | AH2: 2900 | AI2: 2900 | AJ2: no | AK2: 350 | AL2: sí | AM2: 25.5 | AN2: 8408GBN | AO2: 2008-03-03 | AP2: 2008 | AQ2: 3 | AR2: C | AS2: DGT | AU2: no | AV2: C | AX2: no | AY2: no | AZ2: Rojo | BA2: rojo | BB2: 2 | BC2: (por segmento) | BE2: chapa | BG2: sí | BK2: 5 | BM2: 125 | BO2: 0 | BP2: 3650 | BQ2: 28 | BR2: modelo+año+km | BT2: vendedor profesional: sin ITP (operación con IVA/REBU, confirmar en factura); revisar: no menciona la ITV; fiabilidad del modelo PENDIENTE de fuente (puntuación neutra) | BU2: Peugeot 207 1.4 Confort (75 CV) | BV2: https://www.ocasionplus.com/coches-segunda-mano/peugeot-207-14-confort-con-116183km-2008-b9auzqaa (payload RSC 'vehicle') /home/user/Alopecia/buscador-coches/raw/ocasionplus/fc0eb20181760918.json | BW2: =MAX(ANIO_ACTUAL-M2,0) | BX2: =N2/MAX(BW2,0.5) | BY2: =F2 | BZ2: =BY2&"|"&INT(M2/SEG_ANIO)*SEG_ANIO | CA2: =BZ2&"|"&INT(N2/SEG_KM)*SEG_KM | CB2: =COUNTIF($BY$2:$BY$209,BY2) | CC2: =COUNTIF($BZ$2:$BZ$209,BZ2) | CD2: =COUNTIF($CA$2:$CA$209,CA2) | CE2: {=IF(N(BQ2)>=MIN_N,BP2,IF(CD2>=MIN_N,MEDIAN(IF($CA$2:$CA$209=CA2,$O$2:$O$209)),IF(CC2>=MIN_N,MEDIAN(IF($BZ$2:$BZ$209=BZ2,$O$2:$O$209)),MEDIAN(IF($BY$2:$BY$209=BY2,$O$2:$O$209)))))} | CF2: =IF(N(BQ2)>=MIN_N,"mercado "&BR2,IF(CD2>=MIN_N,"modelo+año+km",IF(CC2>=MIN_N,"modelo+año","modelo"))) | CG2: =(CE2-O2)/CE2 | CH2: =IF(COUNTIFS(FR_FUEL,K2,FR_YEAR,AP2)>0,1,0) | CI2: =IF(COUNTIFS(FR_FUEL,K2,FR_YEAR,AP2-1)>0,1,0) | CJ2: =IF(N(AQ2)>0,AP2*100+AQ2,IF(AND(CH2=1,CI2=1),(AP2-1)*100+1,AP2*100+1)) | CK2: =IF(OR(K2="hibrido",K2="glp",K2="gnc",K2="phev"),"ECO",IF(K2="electrico","CERO",IF(K2="gasolina",IF(CJ2>=GAS_C_YM,"C",IF(CJ2>=GAS_B_YM,"B","A")),IF(K2="diesel",IF(CJ2>=DIE_C_YM,"C",IF(CJ2>=DIE_B_YM,"B","A")),"")))) | CL2: C | CM2: =IF(AU2="sí","sí",IF(AS2="regla",IF(AND(N(AQ2)=0,CH2=1),"sí","no"),"no")) | CN2: =IFERROR(VLOOKUP(F2,MOD_TBL,16,0),IFERROR(VLOOKUP(E2,OCU_TBL,2,0),NEUTRO)) | CO2: =SUMIFS(MOT_AJUSTE,MOT_MOTOR,G2,MOT_MARCA,E2,MOT_DESDE,"<="&M2,MOT_HASTA,">="&M2)+SUMIFS(MOT_AJUSTE,MOT_MOTOR,G2,MOT_MARCA,"(todas)",MOT_DESDE,"<="&M2,MOT_HASTA,">="&M2)+SUMIFS(MOT_AJUSTE,MOT_MOTOR,"(cualquiera)",MOT_MARCA,E2,MOT_DESDE,"<="&M2,MOT_HASTA,">="&M2) | CP2: =SUMIFS(COMB_AJUSTE,COMB_COMB,K2) | CQ2: =COUNTIFS(MOT_MOTOR,G2,MOT_MARCA,E2,MOT_DESDE,"<="&M2,MOT_HASTA,">="&M2)+COUNTIFS(MOT_MOTOR,G2,MOT_MARCA,"(todas)",MOT_DESDE,"<="&M2,MOT_HASTA,">="&M2)+COUNTIFS(MOT_MOTOR,"(cualquiera)",MOT_MARCA,E2,MOT_DESDE,"<="&M2,MOT_HASTA,">="&M2) | CR2: =IF(AND(K2="diesel",CQ2=0),MIN(CN2,NEUTRO),CN2) | CS2: =MAX(0,MIN(100,CR2+CO2+CP2-IF(AX2="sí",ROB_PEN,0))) | CT2: =100-MAX(0,N2-KM_TOPE_DESDE)/1000*KM_TOPE_PTS | CU2: =MAX(0,MIN(100,50+CG2*PRECIO_PEND,CT2)) | CV2: =MAX(0,100*(1-N2/KM_MAX)) | CW2: =IF(BX2<KMA_SOSP,IF(AA2="sí",100,KMA_PEN),IF(BX2<=KMA_IDEAL_MAX,100,MAX(0,100*(KMA_CERO-BX2)/(KMA_CERO-KMA_IDEAL_MAX)))) | CX2: =MAX(0,MIN(100,100*(M2-ANIO_MIN)/(ANIO_ACTUAL-ANIO_MIN))) | CY2: =W_KMT*CV2+W_KMA*CW2+W_EDAD*CX2 | CZ2: =E2&"|"&G2 | DA2: =IFERROR(VLOOKUP(CZ2,DIST_TBL,2,0),"") | DB2: =E_ITV*(V2="sí")+E_LIBRO*(W2="sí")+E_PROP*IF(Y2=1,1,IF(Y2=2,0.5,0))+E_CORREA*IF(OR(DA2="cadena",AND(X2="sí",BH2="sí")),1,IF(X2="sí",0.5,0))+E_FACT*(BI2="sí") | DC2: =MAX(0,MIN(100,IFERROR(VLOOKUP(CL2,ETQ_TBL,2,0),0)-IF(CM2="sí",ETQ_PEN_DUD,IF(AS2="regla",ETQ_PEN_REGLA,0)))) | DD2: =IF(K2<>"gasolina","",IFERROR(VLOOKUP(F2,CONS_MOD_TBL,2,0),IFERROR(VLOOKUP(L2,CONS_SEG_TBL,2,0),""))) | DE2: =IF(DD2="",NEUTRO,MAX(0,MIN(100,100*(CONS_REF_MAX-DD2)/(CONS_REF_MAX-CONS_REF_MIN)))) | DF2: =IFERROR(VLOOKUP(L2,SEGURO_TBL,3,0),"") | DG2: =IF(DF2="",NEUTRO,MAX(0,MIN(100,100*(SEG_REF_MAX-DF2)/(SEG_REF_MAX-SEG_REF_MIN)))) | DH2: =IFERROR(VLOOKUP(E2,MANT_MARCA_TBL,2,0)+0,NEUTRO) | DI2: =IF(DA2="",NEUTRO,IFERROR(VLOOKUP(DA2,DIST_PTS_TBL,2,0)+0,NEUTRO)) | DJ2: =(DH2+DI2)/2 | DK2: =W_CONS*DE2+W_SEG*DG2+W_MANT*DJ2 | DL2: =IF(N(AB2)>0,AB2,IF(AND(R2="profesional",SG_LEGAL_ON=1),GAR_LEGAL,0)) | DM2: =MAX(0,MIN(100,SG_GAR*MIN(1,DL2/SG_GAR_FULL)+SG_AMPL*(AC2="sí")+SG_KMC*(AF2="sí")+SG_REV*(N(AE2)>0)+SG_DEV*MIN(1,N(AG2)/SG_DEV_FULL)+SG_HIST*(W2="sí")-IF(AND(R2="particular",DL2=0),SG_PART_PEN,0))) | DN2: =IF(BK2="",NEUTRO,MAX(0,MIN(100,BK2/5*100))) | DO2: =IF(BL2="sí",100,IF(BL2="no",0,NEUTRO)) | DP2: =SV_W_NCAP*DN2+SV_W_ESP*DO2 | DQ2: =MAX(0,MIN(100,ATR_BASE+ATR_ACAB*(BD2<>"")+IF(BE2="16+",ATR_LL16,IF(BE2="sí",ATR_LL,0))+ATR_FAROS*(BF2="sí")+ATR_TINT*(BG2="sí")-ATR_CHAPA*(BE2="chapa"))) | DR2: =EST_W_MOD*(BB2-1)/4*100+EST_W_ATR*DQ2 | DS2: =IF(BA2="",NEUTRO,IFERROR(VLOOKUP(BA2,COLOR_TBL,2,0)+0,NEUTRO)) | DT2: =MAX(0,MIN(100,100*N(BM2)/RV_N_FULL)) | DU2: =IF(OR(BN2="",N(BO2)<RV_DIAS_MIN),NEUTRO,MAX(0,MIN(100,100*(RV_DIAS_CERO-BN2)/(RV_DIAS_CERO-RV_DIAS_FULL)))) | DV2: =RV_W_LIQ*DT2+RV_W_DIAS*DU2+RV_W_ETQ*DC2 | DW2: =IFERROR(VLOOKUP(L2,CARR_PEN_TBL,2,0),0) | DX2: =W_FIAB*CS2+W_PRECIO*CU2+W_KMEDAD*CY2+W_ESTADO*DB2+W_USO*DK2+W_SEGURIDAD*DM2+W_SEGVIAL*DP2+W_ESTETICA*DR2+W_COLOR*DS2+W_REVENTA*DV2-DW2-EG2 | DY2: =IF(N(I2)>0,I2,IFERROR(ROUND(_xlfn.NUMBERVALUE(LEFT(G2,FIND(" ",G2&" ")-1),".")*1000,0),99999)) | DZ2: =IF(R2="profesional",0,IF(O2<CUOTA_VALOR_MAX,IF(BW2>ITP_TRAMO_ALTO,SUMIFS(CF_CUOTA,CF_MAS,ITP_TRAMO_ALTO,CF_CCMIN,"<="&DY2,CF_CCMAX,">="&DY2),IF(BW2>ITP_TRAMO_BAJO,SUMIFS(CF_CUOTA,CF_MAS,ITP_TRAMO_BAJO,CF_CCMIN,"<="&DY2,CF_CCMAX,">="&DY2),O2*ITP_TIPO)),O2*ITP_TIPO)) | EA2: =IF(R2="profesional",N(AK2),0) | EB2: =IF(AND(R2="profesional",ISNUMBER(AK2),AL2="sí"),0,TASA_DGT) | EC2: =INFORME_DGT | ED2: =O2+EA2+DZ2+EB2+EC2 | EE2: =ED2+N(DF2) | EF2: =MAX(0,ED2-TOTAL_MAX) | EG2: =EF2/100*PEN_100 | EH2: =IF(R2="particular",ED2+IF(AND(DA2<>"cadena",X2<>"sí"),RES_CORREA,0)+IF(AND(BJ2<>"sí",BW2>=RES_NEUM_EDAD),RES_NEUM,0),"") | EI2: =IF(ED2<=TOTAL_MAX,"sí",IF(ED2<=TECHO,"negociar","no")) | EJ2: =ROUND(DX2,9) | EK2: =IF(EI2<>"no",SUMPRODUCT(($EI$2:$EI$209<>"no")*($EJ$2:$EJ$209>EJ2))+SUMPRODUCT(($EI$2:EI2<>"no")*($EJ$2:EJ2=EJ2)),"")
A3: autoscout24:827f958f-8688-4b6d-8737-916b285573e8 | B3: autoscout24 | C3: https://www.autoscout24.es/anuncios/volkswagen-polo-1-2-advance-bmt-gasolina-gris-cat_ma74mo2090-827f958f-8688-4b6d-8737-916b285573e8 | D3: Volkswagen Polo 1.2 Advance BMT | E3: Volkswagen | F3: Volkswagen Polo | G3: 1.2 | H3: 1.2 Advance BMT 1.2 | I3: 1198 | J3: 69 | K3: gasolina | L3: utilitario | M3: 2011 | N3: 211000 | O3: 4400 | P3: manual | Q3: no | R3: profesional | S3: Star Car Valencia — ALDAIA (46960) | U3: 8 | Z3: sí | AB3: 24 | AH3: 4400 | AM3: 6.8 | AO3: 2011-07 | AP3: 2011 | AQ3: 7 | AS3: regla | AU3: no | AV3: C | AX3: no | AY3: no | AZ3: Gris | BA3: gris_medio | BB3: 2 | BC3: (por segmento) | BK3: 5 | BL3: sí | BM3: 321 | BN3: 0.051261574 | BO3: 3 | BP3: 4900 | BQ3: 9 | BR3: modelo+año+km | BT3: vendedor profesional: sin ITP (operación con IVA/REBU, confirmar en factura); gastos de gestión del vendedor no indicados: se suma la tasa DGT; preguntar el precio final; etiqueta C deducida por fecha (sin matrícula ni dato del anuncio) | BU3: <strong>Precio al contado: 4400 euros</strong> <br /><br /><strong>Condiciones de la financiación</strong> <br /><br />REQUISITOS<br />LTIMA NOMINA<br />TITULARIDAD BANCARIA<br />DNI<br />TELEFONO<br />⅕<br /> <br /><br />1 AÑO DE GARANTÍA o 2 AÑOS DE GARANTÍA DE MOTOR<br />POSIBILIDAD DE FINANCIACION 100%<br />MANTENIMIENTO REALIZADO<br />ENTREGA INMEDIATA<br />1ª Matriculación: 02/2011<br />Lectura cuentakilómetros: 211.407 km<br />Combustible: Gasolina<br />Potencia: 51 KW / 70 CV<br />Cilindrada: 1.198 cc<br />Caja de cambios: Cambio tipo manual<br />Fecha de vencimiento ITV: 01/2027<br /> Si necesitas cualquier coche — modelo, color, año y kilómetros — te lo traemos.<br />Dinos qué necesitas y lo tendrás. <br /><br /> El anuncio puede contener errores.<br /><br /> | BV3: https://www.autoscout24.es/anuncios/volkswagen-polo-1-2-advance-bmt-gasolina-gris-cat_ma74mo2090-827f958f-8688-4b6d-8737-916b285573e8 (__NEXT_DATA__ listingDetails) /home/user/Alopecia/buscador-coches/raw/autoscout24/d6fff8df76fd308b.json | BW3: =MAX(ANIO_ACTUAL-M3,0) | BX3: =N3/MAX(BW3,0.5) | BY3: =F3 | BZ3: =BY3&"|"&INT(M3/SEG_ANIO)*SEG_ANIO | CA3: =BZ3&"|"&INT(N3/SEG_KM)*SEG_KM | CB3: =COUNTIF($BY$2:$BY$209,BY3) | CC3: =COUNTIF($BZ$2:$BZ$209,BZ3) | CD3: =COUNTIF($CA$2:$CA$209,CA3) | CE3: {=IF(N(BQ3)>=MIN_N,BP3,IF(CD3>=MIN_N,MEDIAN(IF($CA$2:$CA$209=CA3,$O$2:$O$209)),IF(CC3>=MIN_N,MEDIAN(IF($BZ$2:$BZ$209=BZ3,$O$2:$O$209)),MEDIAN(IF($BY$2:$BY$209=BY3,$O$2:$O$209)))))} | CF3: =IF(N(BQ3)>=MIN_N,"mercado "&BR3,IF(CD3>=MIN_N,"modelo+año+km",IF(CC3>=MIN_N,"modelo+año","modelo"))) | CG3: =(CE3-O3)/CE3 | CH3: =IF(COUNTIFS(FR_FUEL,K3,FR_YEAR,AP3)>0,1,0) | CI3: =IF(COUNTIFS(FR_FUEL,K3,FR_YEAR,AP3-1)>0,1,0) | CJ3: =IF(N(AQ3)>0,AP3*100+AQ3,IF(AND(CH3=1,CI3=1),(AP3-1)*100+1,AP3*100+1)) | CK3: =IF(OR(K3="hibrido",K3="glp",K3="gnc",K3="phev"),"ECO",IF(K3="electrico","CERO",IF(K3="gasolina",IF(CJ3>=GAS_C_YM,"C",IF(CJ3>=GAS_B_YM,"B","A")),IF(K3="diesel",IF(CJ3>=DIE_C_YM,"C",IF(CJ3>=DIE_B_YM,"B","A")),"")))) | CL3: =CK3 | CM3: =IF(AU3="sí","sí",IF(AS3="regla",IF(AND(N(AQ3)=0,CH3=1),"sí","no"),"no")) | CN3: =IFERROR(VLOOKUP(F3,MOD_TBL,16,0),IFERROR(VLOOKUP(E3,OCU_TBL,2,0),NEUTRO)) | CO3: =SUMIFS(MOT_AJUSTE,MOT_MOTOR,G3,MOT_MARCA,E3,MOT_DESDE,"<="&M3,MOT_HASTA,">="&M3)+SUMIFS(MOT_AJUSTE,MOT_MOTOR,G3,MOT_MARCA,"(todas)",MOT_DESDE,"<="&M3,MOT_HASTA,">="&M3)+SUMIFS(MOT_AJUSTE,MOT_MOTOR,"(cualquiera)",MOT_MARCA,E3,MOT_DESDE,"<="&M3,MOT_HASTA,">="&M3) | CP3: =SUMIFS(COMB_AJUSTE,COMB_COMB,K3) | CQ3: =COUNTIFS(MOT_MOTOR,G3,MOT_MARCA,E3,MOT_DESDE,"<="&M3,MOT_HASTA,">="&M3)+COUNTIFS(MOT_MOTOR,G3,MOT_MARCA,"(todas)",MOT_DESDE,"<="&M3,MOT_HASTA,">="&M3)+COUNTIFS(MOT_MOTOR,"(cualquiera)",MOT_MARCA,E3,MOT_DESDE,"<="&M3,MOT_HASTA,">="&M3) | CR3: =IF(AND(K3="diesel",CQ3=0),MIN(CN3,NEUTRO),CN3) | CS3: =MAX(0,MIN(100,CR3+CO3+CP3-IF(AX3="sí",ROB_PEN,0))) | CT3: =100-MAX(0,N3-KM_TOPE_DESDE)/1000*KM_TOPE_PTS | CU3: =MAX(0,MIN(100,50+CG3*PRECIO_PEND,CT3)) | CV3: =MAX(0,100*(1-N3/KM_MAX)) | CW3: =IF(BX3<KMA_SOSP,IF(AA3="sí",100,KMA_PEN),IF(BX3<=KMA_IDEAL_MAX,100,MAX(0,100*(KMA_CERO-BX3)/(KMA_CERO-KMA_IDEAL_MAX)))) | CX3: =MAX(0,MIN(100,100*(M3-ANIO_MIN)/(ANIO_ACTUAL-ANIO_MIN))) | CY3: =W_KMT*CV3+W_KMA*CW3+W_EDAD*CX3 | CZ3: =E3&"|"&G3 | DA3: =IFERROR(VLOOKUP(CZ3,DIST_TBL,2,0),"") | DB3: =E_ITV*(V3="sí")+E_LIBRO*(W3="sí")+E_PROP*IF(Y3=1,1,IF(Y3=2,0.5,0))+E_CORREA*IF(OR(DA3="cadena",AND(X3="sí",BH3="sí")),1,IF(X3="sí",0.5,0))+E_FACT*(BI3="sí") | DC3: =MAX(0,MIN(100,IFERROR(VLOOKUP(CL3,ETQ_TBL,2,0),0)-IF(CM3="sí",ETQ_PEN_DUD,IF(AS3="regla",ETQ_PEN_REGLA,0)))) | DD3: =IF(K3<>"gasolina","",IFERROR(VLOOKUP(F3,CONS_MOD_TBL,2,0),IFERROR(VLOOKUP(L3,CONS_SEG_TBL,2,0),""))) | DE3: =IF(DD3="",NEUTRO,MAX(0,MIN(100,100*(CONS_REF_MAX-DD3)/(CONS_REF_MAX-CONS_REF_MIN)))) | DF3: =IFERROR(VLOOKUP(L3,SEGURO_TBL,3,0),"") | DG3: =IF(DF3="",NEUTRO,MAX(0,MIN(100,100*(SEG_REF_MAX-DF3)/(SEG_REF_MAX-SEG_REF_MIN)))) | DH3: =IFERROR(VLOOKUP(E3,MANT_MARCA_TBL,2,0)+0,NEUTRO) | DI3: =IF(DA3="",NEUTRO,IFERROR(VLOOKUP(DA3,DIST_PTS_TBL,2,0)+0,NEUTRO)) | DJ3: =(DH3+DI3)/2 | DK3: =W_CONS*DE3+W_SEG*DG3+W_MANT*DJ3 | DL3: =IF(N(AB3)>0,AB3,IF(AND(R3="profesional",SG_LEGAL_ON=1),GAR_LEGAL,0)) | DM3: =MAX(0,MIN(100,SG_GAR*MIN(1,DL3/SG_GAR_FULL)+SG_AMPL*(AC3="sí")+SG_KMC*(AF3="sí")+SG_REV*(N(AE3)>0)+SG_DEV*MIN(1,N(AG3)/SG_DEV_FULL)+SG_HIST*(W3="sí")-IF(AND(R3="particular",DL3=0),SG_PART_PEN,0))) | DN3: =IF(BK3="",NEUTRO,MAX(0,MIN(100,BK3/5*100))) | DO3: =IF(BL3="sí",100,IF(BL3="no",0,NEUTRO)) | DP3: =SV_W_NCAP*DN3+SV_W_ESP*DO3 | DQ3: =MAX(0,MIN(100,ATR_BASE+ATR_ACAB*(BD3<>"")+IF(BE3="16+",ATR_LL16,IF(BE3="sí",ATR_LL,0))+ATR_FAROS*(BF3="sí")+ATR_TINT*(BG3="sí")-ATR_CHAPA*(BE3="chapa"))) | DR3: =EST_W_MOD*(BB3-1)/4*100+EST_W_ATR*DQ3 | DS3: =IF(BA3="",NEUTRO,IFERROR(VLOOKUP(BA3,COLOR_TBL,2,0)+0,NEUTRO)) | DT3: =MAX(0,MIN(100,100*N(BM3)/RV_N_FULL)) | DU3: =IF(OR(BN3="",N(BO3)<RV_DIAS_MIN),NEUTRO,MAX(0,MIN(100,100*(RV_DIAS_CERO-BN3)/(RV_DIAS_CERO-RV_DIAS_FULL)))) | DV3: =RV_W_LIQ*DT3+RV_W_DIAS*DU3+RV_W_ETQ*DC3 | DW3: =IFERROR(VLOOKUP(L3,CARR_PEN_TBL,2,0),0) | DX3: =W_FIAB*CS3+W_PRECIO*CU3+W_KMEDAD*CY3+W_ESTADO*DB3+W_USO*DK3+W_SEGURIDAD*DM3+W_SEGVIAL*DP3+W_ESTETICA*DR3+W_COLOR*DS3+W_REVENTA*DV3-DW3-EG3 | DY3: =IF(N(I3)>0,I3,IFERROR(ROUND(_xlfn.NUMBERVALUE(LEFT(G3,FIND(" ",G3&" ")-1),".")*1000,0),99999)) | DZ3: =IF(R3="profesional",0,IF(O3<CUOTA_VALOR_MAX,IF(BW3>ITP_TRAMO_ALTO,SUMIFS(CF_CUOTA,CF_MAS,ITP_TRAMO_ALTO,CF_CCMIN,"<="&DY3,CF_CCMAX,">="&DY3),IF(BW3>ITP_TRAMO_BAJO,SUMIFS(CF_CUOTA,CF_MAS,ITP_TRAMO_BAJO,CF_CCMIN,"<="&DY3,CF_CCMAX,">="&DY3),O3*ITP_TIPO)),O3*ITP_TIPO)) | EA3: =IF(R3="profesional",N(AK3),0) | EB3: =IF(AND(R3="profesional",ISNUMBER(AK3),AL3="sí"),0,TASA_DGT) | EC3: =INFORME_DGT | ED3: =O3+EA3+DZ3+EB3+EC3 | EE3: =ED3+N(DF3) | EF3: =MAX(0,ED3-TOTAL_MAX) | EG3: =EF3/100*PEN_100 | EH3: =IF(R3="particular",ED3+IF(AND(DA3<>"cadena",X3<>"sí"),RES_CORREA,0)+IF(AND(BJ3<>"sí",BW3>=RES_NEUM_EDAD),RES_NEUM,0),"") | EI3: =IF(ED3<=TOTAL_MAX,"sí",IF(ED3<=TECHO,"negociar","no")) | EJ3: =ROUND(DX3,9) | EK3: =IF(EI3<>"no",SUMPRODUCT(($EI$2:$EI$209<>"no")*($EJ$2:$EJ$209>EJ3))+SUMPRODUCT(($EI$2:EI3<>"no")*($EJ$2:EJ3=EJ3)),"")
A4: autoscout24:530a78a6-41a7-4caa-9407-81ae2c44ad35 | B4: autoscout24 | C4: https://www.autoscout24.es/anuncios/opel-corsa-1-4-c-mon-139co2-gasolina-gris-cat_ma54mo1918-530a78a6-41a7-4caa-9407-81ae2c44ad35 | D4: Opel Corsa 1.4 C Mon (139CO2) | E4: Opel | F4: Opel Corsa | G4: 1.4 | H4: 1.4 C Mon (139CO2) 1.4 | I4: 1364 | J4: 90 | K4: gasolina | L4: utilitario | M4: 2009 | N4: 136000 | O4: 4500 | P4: manual | Q4: no | R4: profesional | S4: EUROREPAR AUTOS MERCHAN — MASANASSA (46470) | U4: 8 | V4: sí | Z4: sí | AB4: 12 | AM4: 6.7 | AO4: 2009-01 | AP4: 2009 | AQ4: 1 | AS4: regla | AU4: no | AV4: C | AX4: no | AY4: no | AZ4: Gris Metalizado | BA4: gris_medio | BB4: 2 | BC4: (por segmento) | BE4: sí | BJ4: sí | BK4: 5 | BM4: 456 | BN4: 0.051261574 | BO4: 11 | BP4: 3600 | BQ4: 9 | BR4: modelo+año+km | BS4: cochesnet:71842537 (https://www.coches.net/opel-corsa-cmon-14-3p-gasolina-2009-en-valencia-71842537-covo.aspx) | BT4: vendedor profesional: sin ITP (operación con IVA/REBU, confirmar en factura); gastos de gestión del vendedor no indicados: se suma la tasa DGT; preguntar el precio final; etiqueta C deducida por fecha (sin matrícula ni dato del anuncio) | BU4: Se vende Opel Corsa 1.4 Gasolina (90CV) y fecha matriculación Enero 2009. Vehiculo muy bien cuidado tanto interior como exterior y motor . Se entrega con revisión completa aceite y filtros, bujías , 4 neumáticos nuevos, 2 llaves e itv recién pasada.<br /><br /> | BV4: https://www.autoscout24.es/anuncios/opel-corsa-1-4-c-mon-139co2-gasolina-gris-cat_ma54mo1918-530a78a6-41a7-4caa-9407-81ae2c44ad35 (__NEXT_DATA__ listingDetails) /home/user/Alopecia/buscador-coches/raw/autoscout24/ea1df8b55d5dba3e.json | BW4: =MAX(ANIO_ACTUAL-M4,0) | BX4: =N4/MAX(BW4,0.5) | BY4: =F4 | BZ4: =BY4&"|"&INT(M4/SEG_ANIO)*SEG_ANIO | CA4: =BZ4&"|"&INT(N4/SEG_KM)*SEG_KM | CB4: =COUNTIF($BY$2:$BY$209,BY4) | CC4: =COUNTIF($BZ$2:$BZ$209,BZ4) | CD4: =COUNTIF($CA$2:$CA$209,CA4) | CE4: {=IF(N(BQ4)>=MIN_N,BP4,IF(CD4>=MIN_N,MEDIAN(IF($CA$2:$CA$209=CA4,$O$2:$O$209)),IF(CC4>=MIN_N,MEDIAN(IF($BZ$2:$BZ$209=BZ4,$O$2:$O$209)),MEDIAN(IF($BY$2:$BY$209=BY4,$O$2:$O$209)))))} | CF4: =IF(N(BQ4)>=MIN_N,"mercado "&BR4,IF(CD4>=MIN_N,"modelo+año+km",IF(CC4>=MIN_N,"modelo+año","modelo"))) | CG4: =(CE4-O4)/CE4 | CH4: =IF(COUNTIFS(FR_FUEL,K4,FR_YEAR,AP4)>0,1,0) | CI4: =IF(COUNTIFS(FR_FUEL,K4,FR_YEAR,AP4-1)>0,1,0) | CJ4: =IF(N(AQ4)>0,AP4*100+AQ4,IF(AND(CH4=1,CI4=1),(AP4-1)*100+1,AP4*100+1)) | CK4: =IF(OR(K4="hibrido",K4="glp",K4="gnc",K4="phev"),"ECO",IF(K4="electrico","CERO",IF(K4="gasolina",IF(CJ4>=GAS_C_YM,"C",IF(CJ4>=GAS_B_YM,"B","A")),IF(K4="diesel",IF(CJ4>=DIE_C_YM,"C",IF(CJ4>=DIE_B_YM,"B","A")),"")))) | CL4: =CK4 | CM4: =IF(AU4="sí","sí",IF(AS4="regla",IF(AND(N(AQ4)=0,CH4=1),"sí","no"),"no")) | CN4: =IFERROR(VLOOKUP(F4,MOD_TBL,16,0),IFERROR(VLOOKUP(E4,OCU_TBL,2,0),NEUTRO)) | CO4: =SUMIFS(MOT_AJUSTE,MOT_MOTOR,G4,MOT_MARCA,E4,MOT_DESDE,"<="&M4,MOT_HASTA,">="&M4)+SUMIFS(MOT_AJUSTE,MOT_MOTOR,G4,MOT_MARCA,"(todas)",MOT_DESDE,"<="&M4,MOT_HASTA,">="&M4)+SUMIFS(MOT_AJUSTE,MOT_MOTOR,"(cualquiera)",MOT_MARCA,E4,MOT_DESDE,"<="&M4,MOT_HASTA,">="&M4) | CP4: =SUMIFS(COMB_AJUSTE,COMB_COMB,K4) | CQ4: =COUNTIFS(MOT_MOTOR,G4,MOT_MARCA,E4,MOT_DESDE,"<="&M4,MOT_HASTA,">="&M4)+COUNTIFS(MOT_MOTOR,G4,MOT_MARCA,"(todas)",MOT_DESDE,"<="&M4,MOT_HASTA,">="&M4)+COUNTIFS(MOT_MOTOR,"(cualquiera)",MOT_MARCA,E4,MOT_DESDE,"<="&M4,MOT_HASTA,">="&M4) | CR4: =IF(AND(K4="diesel",CQ4=0),MIN(CN4,NEUTRO),CN4) | CS4: =MAX(0,MIN(100,CR4+CO4+CP4-IF(AX4="sí",ROB_PEN,0))) | CT4: =100-MAX(0,N4-KM_TOPE_DESDE)/1000*KM_TOPE_PTS | CU4: =MAX(0,MIN(100,50+CG4*PRECIO_PEND,CT4)) | CV4: =MAX(0,100*(1-N4/KM_MAX)) | CW4: =IF(BX4<KMA_SOSP,IF(AA4="sí",100,KMA_PEN),IF(BX4<=KMA_IDEAL_MAX,100,MAX(0,100*(KMA_CERO-BX4)/(KMA_CERO-KMA_IDEAL_MAX)))) | CX4: =MAX(0,MIN(100,100*(M4-ANIO_MIN)/(ANIO_ACTUAL-ANIO_MIN))) | CY4: =W_KMT*CV4+W_KMA*CW4+W_EDAD*CX4 | CZ4: =E4&"|"&G4 | DA4: =IFERROR(VLOOKUP(CZ4,DIST_TBL,2,0),"") | DB4: =E_ITV*(V4="sí")+E_LIBRO*(W4="sí")+E_PROP*IF(Y4=1,1,IF(Y4=2,0.5,0))+E_CORREA*IF(OR(DA4="cadena",AND(X4="sí",BH4="sí")),1,IF(X4="sí",0.5,0))+E_FACT*(BI4="sí") | DC4: =MAX(0,MIN(100,IFERROR(VLOOKUP(CL4,ETQ_TBL,2,0),0)-IF(CM4="sí",ETQ_PEN_DUD,IF(AS4="regla",ETQ_PEN_REGLA,0)))) | DD4: =IF(K4<>"gasolina","",IFERROR(VLOOKUP(F4,CONS_MOD_TBL,2,0),IFERROR(VLOOKUP(L4,CONS_SEG_TBL,2,0),""))) | DE4: =IF(DD4="",NEUTRO,MAX(0,MIN(100,100*(CONS_REF_MAX-DD4)/(CONS_REF_MAX-CONS_REF_MIN)))) | DF4: =IFERROR(VLOOKUP(L4,SEGURO_TBL,3,0),"") | DG4: =IF(DF4="",NEUTRO,MAX(0,MIN(100,100*(SEG_REF_MAX-DF4)/(SEG_REF_MAX-SEG_REF_MIN)))) | DH4: =IFERROR(VLOOKUP(E4,MANT_MARCA_TBL,2,0)+0,NEUTRO) | DI4: =IF(DA4="",NEUTRO,IFERROR(VLOOKUP(DA4,DIST_PTS_TBL,2,0)+0,NEUTRO)) | DJ4: =(DH4+DI4)/2 | DK4: =W_CONS*DE4+W_SEG*DG4+W_MANT*DJ4 | DL4: =IF(N(AB4)>0,AB4,IF(AND(R4="profesional",SG_LEGAL_ON=1),GAR_LEGAL,0)) | DM4: =MAX(0,MIN(100,SG_GAR*MIN(1,DL4/SG_GAR_FULL)+SG_AMPL*(AC4="sí")+SG_KMC*(AF4="sí")+SG_REV*(N(AE4)>0)+SG_DEV*MIN(1,N(AG4)/SG_DEV_FULL)+SG_HIST*(W4="sí")-IF(AND(R4="particular",DL4=0),SG_PART_PEN,0))) | DN4: =IF(BK4="",NEUTRO,MAX(0,MIN(100,BK4/5*100))) | DO4: =IF(BL4="sí",100,IF(BL4="no",0,NEUTRO)) | DP4: =SV_W_NCAP*DN4+SV_W_ESP*DO4 | DQ4: =MAX(0,MIN(100,ATR_BASE+ATR_ACAB*(BD4<>"")+IF(BE4="16+",ATR_LL16,IF(BE4="sí",ATR_LL,0))+ATR_FAROS*(BF4="sí")+ATR_TINT*(BG4="sí")-ATR_CHAPA*(BE4="chapa"))) | DR4: =EST_W_MOD*(BB4-1)/4*100+EST_W_ATR*DQ4 | DS4: =IF(BA4="",NEUTRO,IFERROR(VLOOKUP(BA4,COLOR_TBL,2,0)+0,NEUTRO)) | DT4: =MAX(0,MIN(100,100*N(BM4)/RV_N_FULL)) | DU4: =IF(OR(BN4="",N(BO4)<RV_DIAS_MIN),NEUTRO,MAX(0,MIN(100,100*(RV_DIAS_CERO-BN4)/(RV_DIAS_CERO-RV_DIAS_FULL)))) | DV4: =RV_W_LIQ*DT4+RV_W_DIAS*DU4+RV_W_ETQ*DC4 | DW4: =IFERROR(VLOOKUP(L4,CARR_PEN_TBL,2,0),0) | DX4: =W_FIAB*CS4+W_PRECIO*CU4+W_KMEDAD*CY4+W_ESTADO*DB4+W_USO*DK4+W_SEGURIDAD*DM4+W_SEGVIAL*DP4+W_ESTETICA*DR4+W_COLOR*DS4+W_REVENTA*DV4-DW4-EG4 | DY4: =IF(N(I4)>0,I4,IFERROR(ROUND(_xlfn.NUMBERVALUE(LEFT(G4,FIND(" ",G4&" ")-1),".")*1000,0),99999)) | DZ4: =IF(R4="profesional",0,IF(O4<CUOTA_VALOR_MAX,IF(BW4>ITP_TRAMO_ALTO,SUMIFS(CF_CUOTA,CF_MAS,ITP_TRAMO_ALTO,CF_CCMIN,"<="&DY4,CF_CCMAX,">="&DY4),IF(BW4>ITP_TRAMO_BAJO,SUMIFS(CF_CUOTA,CF_MAS,ITP_TRAMO_BAJO,CF_CCMIN,"<="&DY4,CF_CCMAX,">="&DY4),O4*ITP_TIPO)),O4*ITP_TIPO)) | EA4: =IF(R4="profesional",N(AK4),0) | EB4: =IF(AND(R4="profesional",ISNUMBER(AK4),AL4="sí"),0,TASA_DGT) | EC4: =INFORME_DGT | ED4: =O4+EA4+DZ4+EB4+EC4 | EE4: =ED4+N(DF4) | EF4: =MAX(0,ED4-TOTAL_MAX) | EG4: =EF4/100*PEN_100 | EH4: =IF(R4="particular",ED4+IF(AND(DA4<>"cadena",X4<>"sí"),RES_CORREA,0)+IF(AND(BJ4<>"sí",BW4>=RES_NEUM_EDAD),RES_NEUM,0),"") | EI4: =IF(ED4<=TOTAL_MAX,"sí",IF(ED4<=TECHO,"negociar","no")) | EJ4: =ROUND(DX4,9) | EK4: =IF(EI4<>"no",SUMPRODUCT(($EI$2:$EI$209<>"no")*($EJ$2:$EJ$209>EJ4))+SUMPRODUCT(($EI$2:EI4<>"no")*($EJ$2:EJ4=EJ4)),"")
A5: autoscout24:eff1fd1c-995f-4e05-b13f-0025ae2ba8f5 | B5: autoscout24 | C5: https://www.autoscout24.es/anuncios/opel-astra-1-7cdti-enjoy-diesel-azul-cat_ma54mo1916-eff1fd1c-995f-4e05-b13f-0025ae2ba8f5 | D5: Opel Astra 1.7CDTi Enjoy | E5: Opel | F5: Opel Astra | G5: 1.7 | H5: 1.7CDTi Enjoy 1.7 | I5: 1686 | J5: 99 | K5: diesel | L5: compacto | M5: 2008 | N5: 180065 | O5: 3599 | P5: manual | Q5: no | R5: profesional | S5: AUTOS XUQUER — SUECA (46410) | U5: 12 | V5: sí | Z5: sí | AB5: 12 | AM5: 30.8 | AO5: 2008-03 | AP5: 2008 | AQ5: 3 | AS5: regla | AU5: no | AV5: B | AX5: no | AY5: no | AZ5: Azul | BA5: azul | BB5: 3 | BC5: (por segmento) | BE5: sí | BK5: 5 | BM5: 402 | BN5: 0.062800926 | BO5: 4 | BP5: 4300 | BQ5: 18 | BR5: modelo+año+km | BT5: vendedor profesional: sin ITP (operación con IVA/REBU, confirmar en factura); gastos de gestión del vendedor no indicados: se suma la tasa DGT; preguntar el precio final; diésel: motor sin fuente de fiabilidad (fiabilidad limitada a neutra); etiqueta B deducida por fecha (sin matrícula ni dato del anuncio) | BU5: Opel Astra SW 1.7 CDTI Familiar, espacioso y muy económico<br />¿Buscas un coche espacioso, fiable y que no te haga temblar cada vez que vas a la gasolinera? Este Opel Astra SW es la combinación perfecta entre practicidad para el día a día y confort para viajar.<br />Con su motor 1.7 CDTI de 100 CV, te llevas uno de los motores diésel más duros y contrastados del mercado: consumo muy ajustado y mantenimiento económico. Además, su carrocería familiar te ofrece un maletero amplísimo con boca de carga baja, ideal para familias, viajes con equipaje o para quien necesita espacio extra sin renunciar a la agilidad de un turismo.<br />Volante con control velocidad de crucero, Radio CD, Aire Acondicionado, llantas de aleación, amplio maletero, elevalunas eléctricos. Cuenta con Baca porta equipajes.<br />Coche económico, con revisiones e ITV al dia.<br />En Autos Xúquer Albelda entregamos todos nuestros vehículos totalmente revisados y con garantía de 12 meses incluida. La financiación es 100 % flexible y sin trámites complicados, y te asesoramos en todo el proceso, antes y después de la compra. <br />Cambio de nombre no incluido (+200 €). <br />Visítanos en Sueca (Valencia) o escríbenos para concertar una prueba sin ningún compromiso.<br />Este anuncio no es vinculante y puede contener errores.<br /><br /><br /> | BV5: https://www.autoscout24.es/anuncios/opel-astra-1-7cdti-enjoy-diesel-azul-cat_ma54mo1916-eff1fd1c-995f-4e05-b13f-0025ae2ba8f5 (__NEXT_DATA__ listingDetails) /home/user/Alopecia/buscador-coches/raw/autoscout24/f2becdc4ebbeca89.json | BW5: =MAX(ANIO_ACTUAL-M5,0) | BX5: =N5/MAX(BW5,0.5) | BY5: =F5 | BZ5: =BY5&"|"&INT(M5/SEG_ANIO)*SEG_ANIO | CA5: =BZ5&"|"&INT(N5/SEG_KM)*SEG_KM | CB5: =COUNTIF($BY$2:$BY$209,BY5) | CC5: =COUNTIF($BZ$2:$BZ$209,BZ5) | CD5: =COUNTIF($CA$2:$CA$209,CA5) | CE5: {=IF(N(BQ5)>=MIN_N,BP5,IF(CD5>=MIN_N,MEDIAN(IF($CA$2:$CA$209=CA5,$O$2:$O$209)),IF(CC5>=MIN_N,MEDIAN(IF($BZ$2:$BZ$209=BZ5,$O$2:$O$209)),MEDIAN(IF($BY$2:$BY$209=BY5,$O$2:$O$209)))))} | CF5: =IF(N(BQ5)>=MIN_N,"mercado "&BR5,IF(CD5>=MIN_N,"modelo+año+km",IF(CC5>=MIN_N,"modelo+año","modelo"))) | CG5: =(CE5-O5)/CE5 | CH5: =IF(COUNTIFS(FR_FUEL,K5,FR_YEAR,AP5)>0,1,0) | CI5: =IF(COUNTIFS(FR_FUEL,K5,FR_YEAR,AP5-1)>0,1,0) | CJ5: =IF(N(AQ5)>0,AP5*100+AQ5,IF(AND(CH5=1,CI5=1),(AP5-1)*100+1,AP5*100+1)) | CK5: =IF(OR(K5="hibrido",K5="glp",K5="gnc",K5="phev"),"ECO",IF(K5="electrico","CERO",IF(K5="gasolina",IF(CJ5>=GAS_C_YM,"C",IF(CJ5>=GAS_B_YM,"B","A")),IF(K5="diesel",IF(CJ5>=DIE_C_YM,"C",IF(CJ5>=DIE_B_YM,"B","A")),"")))) | CL5: =CK5 | CM5: =IF(AU5="sí","sí",IF(AS5="regla",IF(AND(N(AQ5)=0,CH5=1),"sí","no"),"no")) | CN5: =IFERROR(VLOOKUP(F5,MOD_TBL,16,0),IFERROR(VLOOKUP(E5,OCU_TBL,2,0),NEUTRO)) | CO5: =SUMIFS(MOT_AJUSTE,MOT_MOTOR,G5,MOT_MARCA,E5,MOT_DESDE,"<="&M5,MOT_HASTA,">="&M5)+SUMIFS(MOT_AJUSTE,MOT_MOTOR,G5,MOT_MARCA,"(todas)",MOT_DESDE,"<="&M5,MOT_HASTA,">="&M5)+SUMIFS(MOT_AJUSTE,MOT_MOTOR,"(cualquiera)",MOT_MARCA,E5,MOT_DESDE,"<="&M5,MOT_HASTA,">="&M5) | CP5: =SUMIFS(COMB_AJUSTE,COMB_COMB,K5) | CQ5: =COUNTIFS(MOT_MOTOR,G5,MOT_MARCA,E5,MOT_DESDE,"<="&M5,MOT_HASTA,">="&M5)+COUNTIFS(MOT_MOTOR,G5,MOT_MARCA,"(todas)",MOT_DESDE,"<="&M5,MOT_HASTA,">="&M5)+COUNTIFS(MOT_MOTOR,"(cualquiera)",MOT_MARCA,E5,MOT_DESDE,"<="&M5,MOT_HASTA,">="&M5) | CR5: =IF(AND(K5="diesel",CQ5=0),MIN(CN5,NEUTRO),CN5) | CS5: =MAX(0,MIN(100,CR5+CO5+CP5-IF(AX5="sí",ROB_PEN,0))) | CT5: =100-MAX(0,N5-KM_TOPE_DESDE)/1000*KM_TOPE_PTS | CU5: =MAX(0,MIN(100,50+CG5*PRECIO_PEND,CT5)) | CV5: =MAX(0,100*(1-N5/KM_MAX)) | CW5: =IF(BX5<KMA_SOSP,IF(AA5="sí",100,KMA_PEN),IF(BX5<=KMA_IDEAL_MAX,100,MAX(0,100*(KMA_CERO-BX5)/(KMA_CERO-KMA_IDEAL_MAX)))) | CX5: =MAX(0,MIN(100,100*(M5-ANIO_MIN)/(ANIO_ACTUAL-ANIO_MIN))) | CY5: =W_KMT*CV5+W_KMA*CW5+W_EDAD*CX5 | CZ5: =E5&"|"&G5 | DA5: =IFERROR(VLOOKUP(CZ5,DIST_TBL,2,0),"") | DB5: =E_ITV*(V5="sí")+E_LIBRO*(W5="sí")+E_PROP*IF(Y5=1,1,IF(Y5=2,0.5,0))+E_CORREA*IF(OR(DA5="cadena",AND(X5="sí",BH5="sí")),1,IF(X5="sí",0.5,0))+E_FACT*(BI5="sí") | DC5: =MAX(0,MIN(100,IFERROR(VLOOKUP(CL5,ETQ_TBL,2,0),0)-IF(CM5="sí",ETQ_PEN_DUD,IF(AS5="regla",ETQ_PEN_REGLA,0)))) | DD5: =IF(K5<>"gasolina","",IFERROR(VLOOKUP(F5,CONS_MOD_TBL,2,0),IFERROR(VLOOKUP(L5,CONS_SEG_TBL,2,0),""))) | DE5: =IF(DD5="",NEUTRO,MAX(0,MIN(100,100*(CONS_REF_MAX-DD5)/(CONS_REF_MAX-CONS_REF_MIN)))) | DF5: =IFERROR(VLOOKUP(L5,SEGURO_TBL,3,0),"") | DG5: =IF(DF5="",NEUTRO,MAX(0,MIN(100,100*(SEG_REF_MAX-DF5)/(SEG_REF_MAX-SEG_REF_MIN)))) | DH5: =IFERROR(VLOOKUP(E5,MANT_MARCA_TBL,2,0)+0,NEUTRO) | DI5: =IF(DA5="",NEUTRO,IFERROR(VLOOKUP(DA5,DIST_PTS_TBL,2,0)+0,NEUTRO)) | DJ5: =(DH5+DI5)/2 | DK5: =W_CONS*DE5+W_SEG*DG5+W_MANT*DJ5 | DL5: =IF(N(AB5)>0,AB5,IF(AND(R5="profesional",SG_LEGAL_ON=1),GAR_LEGAL,0)) | DM5: =MAX(0,MIN(100,SG_GAR*MIN(1,DL5/SG_GAR_FULL)+SG_AMPL*(AC5="sí")+SG_KMC*(AF5="sí")+SG_REV*(N(AE5)>0)+SG_DEV*MIN(1,N(AG5)/SG_DEV_FULL)+SG_HIST*(W5="sí")-IF(AND(R5="particular",DL5=0),SG_PART_PEN,0))) | DN5: =IF(BK5="",NEUTRO,MAX(0,MIN(100,BK5/5*100))) | DO5: =IF(BL5="sí",100,IF(BL5="no",0,NEUTRO)) | DP5: =SV_W_NCAP*DN5+SV_W_ESP*DO5 | DQ5: =MAX(0,MIN(100,ATR_BASE+ATR_ACAB*(BD5<>"")+IF(BE5="16+",ATR_LL16,IF(BE5="sí",ATR_LL,0))+ATR_FAROS*(BF5="sí")+ATR_TINT*(BG5="sí")-ATR_CHAPA*(BE5="chapa"))) | DR5: =EST_W_MOD*(BB5-1)/4*100+EST_W_ATR*DQ5 | DS5: =IF(BA5="",NEUTRO,IFERROR(VLOOKUP(BA5,COLOR_TBL,2,0)+0,NEUTRO)) | DT5: =MAX(0,MIN(100,100*N(BM5)/RV_N_FULL)) | DU5: =IF(OR(BN5="",N(BO5)<RV_DIAS_MIN),NEUTRO,MAX(0,MIN(100,100*(RV_DIAS_CERO-BN5)/(RV_DIAS_CERO-RV_DIAS_FULL)))) | DV5: =RV_W_LIQ*DT5+RV_W_DIAS*DU5+RV_W_ETQ*DC5 | DW5: =IFERROR(VLOOKUP(L5,CARR_PEN_TBL,2,0),0) | DX5: =W_FIAB*CS5+W_PRECIO*CU5+W_KMEDAD*CY5+W_ESTADO*DB5+W_USO*DK5+W_SEGURIDAD*DM5+W_SEGVIAL*DP5+W_ESTETICA*DR5+W_COLOR*DS5+W_REVENTA*DV5-DW5-EG5 | DY5: =IF(N(I5)>0,I5,IFERROR(ROUND(_xlfn.NUMBERVALUE(LEFT(G5,FIND(" ",G5&" ")-1),".")*1000,0),99999)) | DZ5: =IF(R5="profesional",0,IF(O5<CUOTA_VALOR_MAX,IF(BW5>ITP_TRAMO_ALTO,SUMIFS(CF_CUOTA,CF_MAS,ITP_TRAMO_ALTO,CF_CCMIN,"<="&DY5,CF_CCMAX,">="&DY5),IF(BW5>ITP_TRAMO_BAJO,SUMIFS(CF_CUOTA,CF_MAS,ITP_TRAMO_BAJO,CF_CCMIN,"<="&DY5,CF_CCMAX,">="&DY5),O5*ITP_TIPO)),O5*ITP_TIPO)) | EA5: =IF(R5="profesional",N(AK5),0) | EB5: =IF(AND(R5="profesional",ISNUMBER(AK5),AL5="sí"),0,TASA_DGT) | EC5: =INFORME_DGT | ED5: =O5+EA5+DZ5+EB5+EC5 | EE5: =ED5+N(DF5) | EF5: =MAX(0,ED5-TOTAL_MAX) | EG5: =EF5/100*PEN_100 | EH5: =IF(R5="particular",ED5+IF(AND(DA5<>"cadena",X5<>"sí"),RES_CORREA,0)+IF(AND(BJ5<>"sí",BW5>=RES_NEUM_EDAD),RES_NEUM,0),"") | EI5: =IF(ED5<=TOTAL_MAX,"sí",IF(ED5<=TECHO,"negociar","no")) | EJ5: =ROUND(DX5,9) | EK5: =IF(EI5<>"no",SUMPRODUCT(($EI$2:$EI$209<>"no")*($EJ$2:$EJ$209>EJ5))+SUMPRODUCT(($EI$2:EI5<>"no")*($EJ$2:EJ5=EJ5)),"")
A6: autoscout24:9a094bfd-f634-4d5d-9612-b134882a2a0b | B6: autoscout24 | C6: https://www.autoscout24.es/anuncios/opel-corsa-1-3cdti-c-mon-ecoflex-diesel-cat_ma54mo1918-9a094bfd-f634-4d5d-9612-b134882a2a0b | D6: Opel Corsa 1.3CDTi C Mon ecoFlex | E6: Opel | F6: Opel Corsa | G6: 1.2 CDTi | H6: 1.3CDTi C Mon ecoFlex 1.3 CDTI | I6: 1248 | J6: 75 | K6: diesel | L6: utilitario | M6: 2009 | N6: 172000 | O6: 3990 | P6: manual | Q6: no | R6: profesional | S6: ORLANDO CARS — PATERNA (46980) | U6: 37 | V6: sí | Z6: sí | AB6: 12 | AH6: 3990 | AI6: 3990 | AM6: 9.4 | AO6: 2009-06 | AP6: 2009 | AQ6: 6 | AS6: regla | AU6: no | AV6: B | AX6: no | AY6: no | BB6: 2 | BC6: (por segmento) | BE6: sí | BK6: 5 | BM6: 456 | BN6: 0.051261574 | BO6: 11 | BP6: 3150 | BQ6: 8 | BR6: modelo+año+km | BT6: vendedor profesional: sin ITP (operación con IVA/REBU, confirmar en factura); gastos de gestión del vendedor no indicados: se suma la tasa DGT; preguntar el precio final; diésel: motor sin fuente de fiabilidad (fiabilidad limitada a neutra); etiqueta B deducida por fecha (sin matrícula ni dato del anuncio) | BU6: <strong>Precio al contado: 3990 euros</strong> <br /><br /><strong>Condiciones de la financiación</strong> <br /><br />Precio al contado: 3.990€<br />Precio financiado: 3.990€<br /><br /> <br /><br /><strong>OPEL CORSA ECOFLEX 1.3 75CV</strong><br /><strong> </strong><br /><strong>Nacional – Año 2009</strong><br /><strong>Diesel – Con 172.000Km</strong><br /><strong> </strong><br />Equipado con: -3 Puertas. -2 Llaves. -Bajo consumo. -Radio. -CD. -USB. -AUX. . -Aire acondicionado. -Cierre centralizado. -Airbag. -Elevalunas eléctricos. -Retrovisores eléctricos. -Rueda de repuesto.<br /> <br />Precio al contado: 3.990€<br />Precio financiado: 3.990€<br /> <br /> <br />Aceptamos vehículo como parte de pago. Financiación a medida. Se entrega totalmente revisado, con ITV al día, y 12 meses de garantía. Para más información, estaremos encantados de atenderle en nuestras instalaciones en c/ Ciutat de Llíria, Nº 61 en polígono industrial fuente del jarro, paterna. (cerca de Mislata, Burjasot, Llíria, Bétera, Manises).<br /> <br />Este anuncio es de carácter informativo. Las especificaciones sobre equipamiento, modelo y precio no tienen carácter vinculante, ni puede constituir base de un futuro contrato ya que pueden contener algún error. Consulte con nuestros comerciales la información detallada de este vehículo.<br /> | BV6: https://www.autoscout24.es/anuncios/opel-corsa-1-3cdti-c-mon-ecoflex-diesel-cat_ma54mo1918-9a094bfd-f634-4d5d-9612-b134882a2a0b (__NEXT_DATA__ listingDetails) /home/user/Alopecia/buscador-coches/raw/autoscout24/1927e479532d8469.json | BW6: =MAX(ANIO_ACTUAL-M6,0) | BX6: =N6/MAX(BW6,0.5) | BY6: =F6 | BZ6: =BY6&"|"&INT(M6/SEG_ANIO)*SEG_ANIO | CA6: =BZ6&"|"&INT(N6/SEG_KM)*SEG_KM | CB6: =COUNTIF($BY$2:$BY$209,BY6) | CC6: =COUNTIF($BZ$2:$BZ$209,BZ6) | CD6: =COUNTIF($CA$2:$CA$209,CA6) | CE6: {=IF(N(BQ6)>=MIN_N,BP6,IF(CD6>=MIN_N,MEDIAN(IF($CA$2:$CA$209=CA6,$O$2:$O$209)),IF(CC6>=MIN_N,MEDIAN(IF($BZ$2:$BZ$209=BZ6,$O$2:$O$209)),MEDIAN(IF($BY$2:$BY$209=BY6,$O$2:$O$209)))))} | CF6: =IF(N(BQ6)>=MIN_N,"mercado "&BR6,IF(CD6>=MIN_N,"modelo+año+km",IF(CC6>=MIN_N,"modelo+año","modelo"))) | CG6: =(CE6-O6)/CE6 | CH6: =IF(COUNTIFS(FR_FUEL,K6,FR_YEAR,AP6)>0,1,0) | CI6: =IF(COUNTIFS(FR_FUEL,K6,FR_YEAR,AP6-1)>0,1,0) | CJ6: =IF(N(AQ6)>0,AP6*100+AQ6,IF(AND(CH6=1,CI6=1),(AP6-1)*100+1,AP6*100+1)) | CK6: =IF(OR(K6="hibrido",K6="glp",K6="gnc",K6="phev"),"ECO",IF(K6="electrico","CERO",IF(K6="gasolina",IF(CJ6>=GAS_C_YM,"C",IF(CJ6>=GAS_B_YM,"B","A")),IF(K6="diesel",IF(CJ6>=DIE_C_YM,"C",IF(CJ6>=DIE_B_YM,"B","A")),"")))) | CL6: =CK6 | CM6: =IF(AU6="sí","sí",IF(AS6="regla",IF(AND(N(AQ6)=0,CH6=1),"sí","no"),"no")) | CN6: =IFERROR(VLOOKUP(F6,MOD_TBL,16,0),IFERROR(VLOOKUP(E6,OCU_TBL,2,0),NEUTRO)) | CO6: =SUMIFS(MOT_AJUSTE,MOT_MOTOR,G6,MOT_MARCA,E6,MOT_DESDE,"<="&M6,MOT_HASTA,">="&M6)+SUMIFS(MOT_AJUSTE,MOT_MOTOR,G6,MOT_MARCA,"(todas)",MOT_DESDE,"<="&M6,MOT_HASTA,">="&M6)+SUMIFS(MOT_AJUSTE,MOT_MOTOR,"(cualquiera)",MOT_MARCA,E6,MOT_DESDE,"<="&M6,MOT_HASTA,">="&M6) | CP6: =SUMIFS(COMB_AJUSTE,COMB_COMB,K6) | CQ6: =COUNTIFS(MOT_MOTOR,G6,MOT_MARCA,E6,MOT_DESDE,"<="&M6,MOT_HASTA,">="&M6)+COUNTIFS(MOT_MOTOR,G6,MOT_MARCA,"(todas)",MOT_DESDE,"<="&M6,MOT_HASTA,">="&M6)+COUNTIFS(MOT_MOTOR,"(cualquiera)",MOT_MARCA,E6,MOT_DESDE,"<="&M6,MOT_HASTA,">="&M6) | CR6: =IF(AND(K6="diesel",CQ6=0),MIN(CN6,NEUTRO),CN6) | CS6: =MAX(0,MIN(100,CR6+CO6+CP6-IF(AX6="sí",ROB_PEN,0))) | CT6: =100-MAX(0,N6-KM_TOPE_DESDE)/1000*KM_TOPE_PTS | CU6: =MAX(0,MIN(100,50+CG6*PRECIO_PEND,CT6)) | CV6: =MAX(0,100*(1-N6/KM_MAX)) | CW6: =IF(BX6<KMA_SOSP,IF(AA6="sí",100,KMA_PEN),IF(BX6<=KMA_IDEAL_MAX,100,MAX(0,100*(KMA_CERO-BX6)/(KMA_CERO-KMA_IDEAL_MAX)))) | CX6: =MAX(0,MIN(100,100*(M6-ANIO_MIN)/(ANIO_ACTUAL-ANIO_MIN))) | CY6: =W_KMT*CV6+W_KMA*CW6+W_EDAD*CX6 | CZ6: =E6&"|"&G6 | DA6: =IFERROR(VLOOKUP(CZ6,DIST_TBL,2,0),"") | DB6: =E_ITV*(V6="sí")+E_LIBRO*(W6="sí")+E_PROP*IF(Y6=1,1,IF(Y6=2,0.5,0))+E_CORREA*IF(OR(DA6="cadena",AND(X6="sí",BH6="sí")),1,IF(X6="sí",0.5,0))+E_FACT*(BI6="sí") | DC6: =MAX(0,MIN(100,IFERROR(VLOOKUP(CL6,ETQ_TBL,2,0),0)-IF(CM6="sí",ETQ_PEN_DUD,IF(AS6="regla",ETQ_PEN_REGLA,0)))) | DD6: =IF(K6<>"gasolina","",IFERROR(VLOOKUP(F6,CONS_MOD_TBL,2,0),IFERROR(VLOOKUP(L6,CONS_SEG_TBL,2,0),""))) | DE6: =IF(DD6="",NEUTRO,MAX(0,MIN(100,100*(CONS_REF_MAX-DD6)/(CONS_REF_MAX-CONS_REF_MIN)))) | DF6: =IFERROR(VLOOKUP(L6,SEGURO_TBL,3,0),"") | DG6: =IF(DF6="",NEUTRO,MAX(0,MIN(100,100*(SEG_REF_MAX-DF6)/(SEG_REF_MAX-SEG_REF_MIN)))) | DH6: =IFERROR(VLOOKUP(E6,MANT_MARCA_TBL,2,0)+0,NEUTRO) | DI6: =IF(DA6="",NEUTRO,IFERROR(VLOOKUP(DA6,DIST_PTS_TBL,2,0)+0,NEUTRO)) | DJ6: =(DH6+DI6)/2 | DK6: =W_CONS*DE6+W_SEG*DG6+W_MANT*DJ6 | DL6: =IF(N(AB6)>0,AB6,IF(AND(R6="profesional",SG_LEGAL_ON=1),GAR_LEGAL,0)) | DM6: =MAX(0,MIN(100,SG_GAR*MIN(1,DL6/SG_GAR_FULL)+SG_AMPL*(AC6="sí")+SG_KMC*(AF6="sí")+SG_REV*(N(AE6)>0)+SG_DEV*MIN(1,N(AG6)/SG_DEV_FULL)+SG_HIST*(W6="sí")-IF(AND(R6="particular",DL6=0),SG_PART_PEN,0))) | DN6: =IF(BK6="",NEUTRO,MAX(0,MIN(100,BK6/5*100))) | DO6: =IF(BL6="sí",100,IF(BL6="no",0,NEUTRO)) | DP6: =SV_W_NCAP*DN6+SV_W_ESP*DO6 | DQ6: =MAX(0,MIN(100,ATR_BASE+ATR_ACAB*(BD6<>"")+IF(BE6="16+",ATR_LL16,IF(BE6="sí",ATR_LL,0))+ATR_FAROS*(BF6="sí")+ATR_TINT*(BG6="sí")-ATR_CHAPA*(BE6="chapa"))) | DR6: =EST_W_MOD*(BB6-1)/4*100+EST_W_ATR*DQ6 | DS6: =IF(BA6="",NEUTRO,IFERROR(VLOOKUP(BA6,COLOR_TBL,2,0)+0,NEUTRO)) | DT6: =MAX(0,MIN(100,100*N(BM6)/RV_N_FULL)) | DU6: =IF(OR(BN6="",N(BO6)<RV_DIAS_MIN),NEUTRO,MAX(0,MIN(100,100*(RV_DIAS_CERO-BN6)/(RV_DIAS_CERO-RV_DIAS_FULL)))) | DV6: =RV_W_LIQ*DT6+RV_W_DIAS*DU6+RV_W_ETQ*DC6 | DW6: =IFERROR(VLOOKUP(L6,CARR_PEN_TBL,2,0),0) | DX6: =W_FIAB*CS6+W_PRECIO*CU6+W_KMEDAD*CY6+W_ESTADO*DB6+W_USO*DK6+W_SEGURIDAD*DM6+W_SEGVIAL*DP6+W_ESTETICA*DR6+W_COLOR*DS6+W_REVENTA*DV6-DW6-EG6 | DY6: =IF(N(I6)>0,I6,IFERROR(ROUND(_xlfn.NUMBERVALUE(LEFT(G6,FIND(" ",G6&" ")-1),".")*1000,0),99999)) | DZ6: =IF(R6="profesional",0,IF(O6<CUOTA_VALOR_MAX,IF(BW6>ITP_TRAMO_ALTO,SUMIFS(CF_CUOTA,CF_MAS,ITP_TRAMO_ALTO,CF_CCMIN,"<="&DY6,CF_CCMAX,">="&DY6),IF(BW6>ITP_TRAMO_BAJO,SUMIFS(CF_CUOTA,CF_MAS,ITP_TRAMO_BAJO,CF_CCMIN,"<="&DY6,CF_CCMAX,">="&DY6),O6*ITP_TIPO)),O6*ITP_TIPO)) | EA6: =IF(R6="profesional",N(AK6),0) | EB6: =IF(AND(R6="profesional",ISNUMBER(AK6),AL6="sí"),0,TASA_DGT) | EC6: =INFORME_DGT | ED6: =O6+EA6+DZ6+EB6+EC6 | EE6: =ED6+N(DF6) | EF6: =MAX(0,ED6-TOTAL_MAX) | EG6: =EF6/100*PEN_100 | EH6: =IF(R6="particular",ED6+IF(AND(DA6<>"cadena",X6<>"sí"),RES_CORREA,0)+IF(AND(BJ6<>"sí",BW6>=RES_NEUM_EDAD),RES_NEUM,0),"") | EI6: =IF(ED6<=TOTAL_MAX,"sí",IF(ED6<=TECHO,"negociar","no")) | EJ6: =ROUND(DX6,9) | EK6: =IF(EI6<>"no",SUMPRODUCT(($EI$2:$EI$209<>"no")*($EJ$2:$EJ$209>EJ6))+SUMPRODUCT(($EI$2:EI6<>"no")*($EJ$2:EJ6=EJ6)),"")
A7: wallapop:1313427276 | B7: wallapop | C7: https://es.wallapop.com/item/ford-fiesta-ford-fiesta-1-3-ambiente-1313427276 | D7: Ford Fiesta Ford Fiesta 1.3 Ambiente | E7: Ford | F7: Ford Fiesta | G7: 1.3 | H7: Ford Fiesta 1.3 Ambiente | J7: 70 | K7: gasolina | L7: utilitario | M7: 2008 | N7: 82000 | O7: 3500 | P7: manual | Q7: no | R7: profesional | S7: Manises (46940) | T7: 2026-10-30T18:10:07 | U7: 9 | AM7: 7.2 | AO7: 2008 | AP7: 2008 | AS7: regla | AU7: no | AV7: C | AX7: no | AY7: no | BB7: 2 | BC7: (por segmento) | BK7: 4 | BL7: no | BM7: 302 | BN7: 0.074340278 | BO7: 3 | BP7: 3500 | BQ7: 48 | BR7: modelo+año | BS7: autoscout24:cb47557d-00cb-449b-8153-e5de1e64bdaf (https://www.autoscout24.es/anuncios/ford-fiesta-1-3-ambiente-gasolina-gris-cat_ma29mo1758-cb47557d-00cb-449b-8153-e5de1e64bdaf) | BT7: vendedor profesional: sin ITP (operación con IVA/REBU, confirmar en factura); gastos de gestión del vendedor no indicados: se suma la tasa DGT; preguntar el precio final; etiqueta C deducida por fecha (sin matrícula ni dato del anuncio); revisar: no menciona la ITV | BU7: 🔹- con posibilidad de financiar desde 🔹79€ al mes-🤝🚗 🔹-Ford fiesta 2008 🔹-1.3 60cv gasolina( a cadena) 🔹-82.000 kilómetros 🔹-se entrega totalmente al día 🔹- 1 año de garantía 🔺-3.500€🔻 -SE ACEPTA COCHE INFERIOR COMO PARTE DE PAGO!!🤝🚗 -tiktok @eurocochesmanival -instam eloy_manival (Mini,208,Clío,micra,Ibiza,kalos,picanto,i10,i20,Mazda 2,Golf,polo,a3,Leon,Ibiza,i30,Astra,Megane,307) | BV7: https://es.wallapop.com/item/ford-fiesta-ford-fiesta-1-3-ambiente-1313427276 (__NEXT_DATA__ item) /home/user/Alopecia/buscador-coches/raw/wallapop/564731e59dcd7515.json | BW7: =MAX(ANIO_ACTUAL-M7,0) | BX7: =N7/MAX(BW7,0.5) | BY7: =F7 | BZ7: =BY7&"|"&INT(M7/SEG_ANIO)*SEG_ANIO | CA7: =BZ7&"|"&INT(N7/SEG_KM)*SEG_KM | CB7: =COUNTIF($BY$2:$BY$209,BY7) | CC7: =COUNTIF($BZ$2:$BZ$209,BZ7) | CD7: =COUNTIF($CA$2:$CA$209,CA7) | CE7: {=IF(N(BQ7)>=MIN_N,BP7,IF(CD7>=MIN_N,MEDIAN(IF($CA$2:$CA$209=CA7,$O$2:$O$209)),IF(CC7>=MIN_N,MEDIAN(IF($BZ$2:$BZ$209=BZ7,$O$2:$O$209)),MEDIAN(IF($BY$2:$BY$209=BY7,$O$2:$O$209)))))} | CF7: =IF(N(BQ7)>=MIN_N,"mercado "&BR7,IF(CD7>=MIN_N,"modelo+año+km",IF(CC7>=MIN_N,"modelo+año","modelo"))) | CG7: =(CE7-O7)/CE7 | CH7: =IF(COUNTIFS(FR_FUEL,K7,FR_YEAR,AP7)>0,1,0) | CI7: =IF(COUNTIFS(FR_FUEL,K7,FR_YEAR,AP7-1)>0,1,0) | CJ7: =IF(N(AQ7)>0,AP7*100+AQ7,IF(AND(CH7=1,CI7=1),(AP7-1)*100+1,AP7*100+1)) | CK7: =IF(OR(K7="hibrido",K7="glp",K7="gnc",K7="phev"),"ECO",IF(K7="electrico","CERO",IF(K7="gasolina",IF(CJ7>=GAS_C_YM,"C",IF(CJ7>=GAS_B_YM,"B","A")),IF(K7="diesel",IF(CJ7>=DIE_C_YM,"C",IF(CJ7>=DIE_B_YM,"B","A")),"")))) | CL7: =CK7 | CM7: =IF(AU7="sí","sí",IF(AS7="regla",IF(AND(N(AQ7)=0,CH7=1),"sí","no"),"no")) | CN7: =IFERROR(VLOOKUP(F7,MOD_TBL,16,0),IFERROR(VLOOKUP(E7,OCU_TBL,2,0),NEUTRO)) | CO7: =SUMIFS(MOT_AJUSTE,MOT_MOTOR,G7,MOT_MARCA,E7,MOT_DESDE,"<="&M7,MOT_HASTA,">="&M7)+SUMIFS(MOT_AJUSTE,MOT_MOTOR,G7,MOT_MARCA,"(todas)",MOT_DESDE,"<="&M7,MOT_HASTA,">="&M7)+SUMIFS(MOT_AJUSTE,MOT_MOTOR,"(cualquiera)",MOT_MARCA,E7,MOT_DESDE,"<="&M7,MOT_HASTA,">="&M7) | CP7: =SUMIFS(COMB_AJUSTE,COMB_COMB,K7) | CQ7: =COUNTIFS(MOT_MOTOR,G7,MOT_MARCA,E7,MOT_DESDE,"<="&M7,MOT_HASTA,">="&M7)+COUNTIFS(MOT_MOTOR,G7,MOT_MARCA,"(todas)",MOT_DESDE,"<="&M7,MOT_HASTA,">="&M7)+COUNTIFS(MOT_MOTOR,"(cualquiera)",MOT_MARCA,E7,MOT_DESDE,"<="&M7,MOT_HASTA,">="&M7) | CR7: =IF(AND(K7="diesel",CQ7=0),MIN(CN7,NEUTRO),CN7) | CS7: =MAX(0,MIN(100,CR7+CO7+CP7-IF(AX7="sí",ROB_PEN,0))) | CT7: =100-MAX(0,N7-KM_TOPE_DESDE)/1000*KM_TOPE_PTS | CU7: =MAX(0,MIN(100,50+CG7*PRECIO_PEND,CT7)) | CV7: =MAX(0,100*(1-N7/KM_MAX)) | CW7: =IF(BX7<KMA_SOSP,IF(AA7="sí",100,KMA_PEN),IF(BX7<=KMA_IDEAL_MAX,100,MAX(0,100*(KMA_CERO-BX7)/(KMA_CERO-KMA_IDEAL_MAX)))) | CX7: =MAX(0,MIN(100,100*(M7-ANIO_MIN)/(ANIO_ACTUAL-ANIO_MIN))) | CY7: =W_KMT*CV7+W_KMA*CW7+W_EDAD*CX7 | CZ7: =E7&"|"&G7 | DA7: =IFERROR(VLOOKUP(CZ7,DIST_TBL,2,0),"") | DB7: =E_ITV*(V7="sí")+E_LIBRO*(W7="sí")+E_PROP*IF(Y7=1,1,IF(Y7=2,0.5,0))+E_CORREA*IF(OR(DA7="cadena",AND(X7="sí",BH7="sí")),1,IF(X7="sí",0.5,0))+E_FACT*(BI7="sí") | DC7: =MAX(0,MIN(100,IFERROR(VLOOKUP(CL7,ETQ_TBL,2,0),0)-IF(CM7="sí",ETQ_PEN_DUD,IF(AS7="regla",ETQ_PEN_REGLA,0)))) | DD7: =IF(K7<>"gasolina","",IFERROR(VLOOKUP(F7,CONS_MOD_TBL,2,0),IFERROR(VLOOKUP(L7,CONS_SEG_TBL,2,0),""))) | DE7: =IF(DD7="",NEUTRO,MAX(0,MIN(100,100*(CONS_REF_MAX-DD7)/(CONS_REF_MAX-CONS_REF_MIN)))) | DF7: =IFERROR(VLOOKUP(L7,SEGURO_TBL,3,0),"") | DG7: =IF(DF7="",NEUTRO,MAX(0,MIN(100,100*(SEG_REF_MAX-DF7)/(SEG_REF_MAX-SEG_REF_MIN)))) | DH7: =IFERROR(VLOOKUP(E7,MANT_MARCA_TBL,2,0)+0,NEUTRO) | DI7: =IF(DA7="",NEUTRO,IFERROR(VLOOKUP(DA7,DIST_PTS_TBL,2,0)+0,NEUTRO)) | DJ7: =(DH7+DI7)/2 | DK7: =W_CONS*DE7+W_SEG*DG7+W_MANT*DJ7 | DL7: =IF(N(AB7)>0,AB7,IF(AND(R7="profesional",SG_LEGAL_ON=1),GAR_LEGAL,0)) | DM7: =MAX(0,MIN(100,SG_GAR*MIN(1,DL7/SG_GAR_FULL)+SG_AMPL*(AC7="sí")+SG_KMC*(AF7="sí")+SG_REV*(N(AE7)>0)+SG_DEV*MIN(1,N(AG7)/SG_DEV_FULL)+SG_HIST*(W7="sí")-IF(AND(R7="particular",DL7=0),SG_PART_PEN,0))) | DN7: =IF(BK7="",NEUTRO,MAX(0,MIN(100,BK7/5*100))) | DO7: =IF(BL7="sí",100,IF(BL7="no",0,NEUTRO)) | DP7: =SV_W_NCAP*DN7+SV_W_ESP*DO7 | DQ7: =MAX(0,MIN(100,ATR_BASE+ATR_ACAB*(BD7<>"")+IF(BE7="16+",ATR_LL16,IF(BE7="sí",ATR_LL,0))+ATR_FAROS*(BF7="sí")+ATR_TINT*(BG7="sí")-ATR_CHAPA*(BE7="chapa"))) | DR7: =EST_W_MOD*(BB7-1)/4*100+EST_W_ATR*DQ7 | DS7: =IF(BA7="",NEUTRO,IFERROR(VLOOKUP(BA7,COLOR_TBL,2,0)+0,NEUTRO)) | DT7: =MAX(0,MIN(100,100*N(BM7)/RV_N_FULL)) | DU7: =IF(OR(BN7="",N(BO7)<RV_DIAS_MIN),NEUTRO,MAX(0,MIN(100,100*(RV_DIAS_CERO-BN7)/(RV_DIAS_CERO-RV_DIAS_FULL)))) | DV7: =RV_W_LIQ*DT7+RV_W_DIAS*DU7+RV_W_ETQ*DC7 | DW7: =IFERROR(VLOOKUP(L7,CARR_PEN_TBL,2,0),0) | DX7: =W_FIAB*CS7+W_PRECIO*CU7+W_KMEDAD*CY7+W_ESTADO*DB7+W_USO*DK7+W_SEGURIDAD*DM7+W_SEGVIAL*DP7+W_ESTETICA*DR7+W_COLOR*DS7+W_REVENTA*DV7-DW7-EG7 | DY7: =IF(N(I7)>0,I7,IFERROR(ROUND(_xlfn.NUMBERVALUE(LEFT(G7,FIND(" ",G7&" ")-1),".")*1000,0),99999)) | DZ7: =IF(R7="profesional",0,IF(O7<CUOTA_VALOR_MAX,IF(BW7>ITP_TRAMO_ALTO,SUMIFS(CF_CUOTA,CF_MAS,ITP_TRAMO_ALTO,CF_CCMIN,"<="&DY7,CF_CCMAX,">="&DY7),IF(BW7>ITP_TRAMO_BAJO,SUMIFS(CF_CUOTA,CF_MAS,ITP_TRAMO_BAJO,CF_CCMIN,"<="&DY7,CF_CCMAX,">="&DY7),O7*ITP_TIPO)),O7*ITP_TIPO)) | EA7: =IF(R7="profesional",N(AK7),0) | EB7: =IF(AND(R7="profesional",ISNUMBER(AK7),AL7="sí"),0,TASA_DGT) | EC7: =INFORME_DGT | ED7: =O7+EA7+DZ7+EB7+EC7 | EE7: =ED7+N(DF7) | EF7: =MAX(0,ED7-TOTAL_MAX) | EG7: =EF7/100*PEN_100 | EH7: =IF(R7="particular",ED7+IF(AND(DA7<>"cadena",X7<>"sí"),RES_CORREA,0)+IF(AND(BJ7<>"sí",BW7>=RES_NEUM_EDAD),RES_NEUM,0),"") | EI7: =IF(ED7<=TOTAL_MAX,"sí",IF(ED7<=TECHO,"negociar","no")) | EJ7: =ROUND(DX7,9) | EK7: =IF(EI7<>"no",SUMPRODUCT(($EI$2:$EI$209<>"no")*($EJ$2:$EJ$209>EJ7))+SUMPRODUCT(($EI$2:EI7<>"no")*($EJ$2:EJ7=EJ7)),"")
A8: autoscout24:5df9bdd9-27ce-4647-b70f-976633b13f7a | B8: autoscout24 | C8: https://www.autoscout24.es/anuncios/chevrolet-aveo-sedan-1-4-16v-lt-gasolina-gris-cat_ma19mo18685-5df9bdd9-27ce-4647-b70f-976633b13f7a | D8: Chevrolet Aveo Sedán 1.4 16v LT | E8: Chevrolet | F8: Chevrolet Aveo | G8: 1.4 | H8: Sedán 1.4 16v LT 1.4 | I8: 1399 | J8: 94 | K8: gasolina | L8: berlina | M8: 2008 | N8: 138000 | O8: 3990 | P8: manual | Q8: no | R8: profesional | S8: SAGA VEHICULOS — MASSANASSA (46470) | U8: 26 | Z8: sí | AB8: 12 | AC8: sí | AK8: 350 | AL8: no | AM8: 7.1 | AO8: 2008-10 | AP8: 2008 | AQ8: 10 | AS8: regla | AU8: no | AV8: C | AX8: no | AY8: no | AZ8: Gris | BA8: gris_medio | BB8: 3 | BC8: (por segmento) | BK8: 2 | BL8: no | BM8: 27 | BO8: 0 | BP8: 3990 | BQ8: 4 | BR8: modelo+año+km | BS8: cochesnet:71651301 (https://www.coches.net/chevrolet-aveo-14-16v-lt-4p-gasolina-2008-en-valencia-71651301-covo.aspx) | BT8: vendedor profesional: sin ITP (operación con IVA/REBU, confirmar en factura); gastos del vendedor sin indicar si incluyen la transferencia: se suma la tasa DGT; etiqueta C deducida por fecha (sin matrícula ni dato del anuncio); revisar: no menciona la ITV; fiabilidad del modelo PENDIENTE de fuente (puntuación neutra) | BU8: Chevrolet Aveo LT 1.4 E-TEC ll, 95CV, Gasolina, vehículo muy bien cuidado.<br />Más de 100 coches en stock, Por favor llámenos para más información, atendemos SOLO CON CITA PREVIA. Gracias!!!!<br />Financiacíon de hasta el 100% del vehículo!<br />Gestión documental no incluido 350€ <br />Garantía Premium 12 Meses con cobertura a nivel nacional 399€<br />Saga Vehículos, estamos en C/ Motor Sant Agustí, 41, 46470 Massanassa, Valencia.<br />Horario: De lunes a viernes de 10:00 a 14:00 y de 16:00 a 19:00.<br />Sabado de 10:00 a 14:00.<br />- Aire acondicionado <br />- Dirección asistida<br />- Frenos ABS/EBD<br />- Airbags<br />- Ordenador abordo<br />- Android Auto / Apple CarPlay <br />- Sistema multimedia Bluetooth<br />- GPS navegación <br />- Camara trasera <br />- Llaves presencial con mandos a distancia y mucho mas....<br />Este anuncio no es vinculante, se muestra a titulo informativo y no contractual.<br /><br /><br /><br /> <strong>Extras</strong> <br /> <strong>Equipamiento destacado seleccionado por el usuario</strong> <br /> <br />- Pintura metalizada<br /> | BV8: https://www.autoscout24.es/anuncios/chevrolet-aveo-sedan-1-4-16v-lt-gasolina-gris-cat_ma19mo18685-5df9bdd9-27ce-4647-b70f-976633b13f7a (__NEXT_DATA__ listingDetails) /home/user/Alopecia/buscador-coches/raw/autoscout24/b2dc71ccfcad6c3c.json | BW8: =MAX(ANIO_ACTUAL-M8,0) | BX8: =N8/MAX(BW8,0.5) | BY8: =F8 | BZ8: =BY8&"|"&INT(M8/SEG_ANIO)*SEG_ANIO | CA8: =BZ8&"|"&INT(N8/SEG_KM)*SEG_KM | CB8: =COUNTIF($BY$2:$BY$209,BY8) | CC8: =COUNTIF($BZ$2:$BZ$209,BZ8) | CD8: =COUNTIF($CA$2:$CA$209,CA8) | CE8: {=IF(N(BQ8)>=MIN_N,BP8,IF(CD8>=MIN_N,MEDIAN(IF($CA$2:$CA$209=CA8,$O$2:$O$209)),IF(CC8>=MIN_N,MEDIAN(IF($BZ$2:$BZ$209=BZ8,$O$2:$O$209)),MEDIAN(IF($BY$2:$BY$209=BY8,$O$2:$O$209)))))} | CF8: =IF(N(BQ8)>=MIN_N,"mercado "&BR8,IF(CD8>=MIN_N,"modelo+año+km",IF(CC8>=MIN_N,"modelo+año","modelo"))) | CG8: =(CE8-O8)/CE8 | CH8: =IF(COUNTIFS(FR_FUEL,K8,FR_YEAR,AP8)>0,1,0) | CI8: =IF(COUNTIFS(FR_FUEL,K8,FR_YEAR,AP8-1)>0,1,0) | CJ8: =IF(N(AQ8)>0,AP8*100+AQ8,IF(AND(CH8=1,CI8=1),(AP8-1)*100+1,AP8*100+1)) | CK8: =IF(OR(K8="hibrido",K8="glp",K8="gnc",K8="phev"),"ECO",IF(K8="electrico","CERO",IF(K8="gasolina",IF(CJ8>=GAS_C_YM,"C",IF(CJ8>=GAS_B_YM,"B","A")),IF(K8="diesel",IF(CJ8>=DIE_C_YM,"C",IF(CJ8>=DIE_B_YM,"B","A")),"")))) | CL8: =CK8 | CM8: =IF(AU8="sí","sí",IF(AS8="regla",IF(AND(N(AQ8)=0,CH8=1),"sí","no"),"no")) | CN8: =IFERROR(VLOOKUP(F8,MOD_TBL,16,0),IFERROR(VLOOKUP(E8,OCU_TBL,2,0),NEUTRO)) | CO8: =SUMIFS(MOT_AJUSTE,MOT_MOTOR,G8,MOT_MARCA,E8,MOT_DESDE,"<="&M8,MOT_HASTA,">="&M8)+SUMIFS(MOT_AJUSTE,MOT_MOTOR,G8,MOT_MARCA,"(todas)",MOT_DESDE,"<="&M8,MOT_HASTA,">="&M8)+SUMIFS(MOT_AJUSTE,MOT_MOTOR,"(cualquiera)",MOT_MARCA,E8,MOT_DESDE,"<="&M8,MOT_HASTA,">="&M8) | CP8: =SUMIFS(COMB_AJUSTE,COMB_COMB,K8) | CQ8: =COUNTIFS(MOT_MOTOR,G8,MOT_MARCA,E8,MOT_DESDE,"<="&M8,MOT_HASTA,">="&M8)+COUNTIFS(MOT_MOTOR,G8,MOT_MARCA,"(todas)",MOT_DESDE,"<="&M8,MOT_HASTA,">="&M8)+COUNTIFS(MOT_MOTOR,"(cualquiera)",MOT_MARCA,E8,MOT_DESDE,"<="&M8,MOT_HASTA,">="&M8) | CR8: =IF(AND(K8="diesel",CQ8=0),MIN(CN8,NEUTRO),CN8) | CS8: =MAX(0,MIN(100,CR8+CO8+CP8-IF(AX8="sí",ROB_PEN,0))) | CT8: =100-MAX(0,N8-KM_TOPE_DESDE)/1000*KM_TOPE_PTS | CU8: =MAX(0,MIN(100,50+CG8*PRECIO_PEND,CT8)) | CV8: =MAX(0,100*(1-N8/KM_MAX)) | CW8: =IF(BX8<KMA_SOSP,IF(AA8="sí",100,KMA_PEN),IF(BX8<=KMA_IDEAL_MAX,100,MAX(0,100*(KMA_CERO-BX8)/(KMA_CERO-KMA_IDEAL_MAX)))) | CX8: =MAX(0,MIN(100,100*(M8-ANIO_MIN)/(ANIO_ACTUAL-ANIO_MIN))) | CY8: =W_KMT*CV8+W_KMA*CW8+W_EDAD*CX8 | CZ8: =E8&"|"&G8 | DA8: =IFERROR(VLOOKUP(CZ8,DIST_TBL,2,0),"") | DB8: =E_ITV*(V8="sí")+E_LIBRO*(W8="sí")+E_PROP*IF(Y8=1,1,IF(Y8=2,0.5,0))+E_CORREA*IF(OR(DA8="cadena",AND(X8="sí",BH8="sí")),1,IF(X8="sí",0.5,0))+E_FACT*(BI8="sí") | DC8: =MAX(0,MIN(100,IFERROR(VLOOKUP(CL8,ETQ_TBL,2,0),0)-IF(CM8="sí",ETQ_PEN_DUD,IF(AS8="regla",ETQ_PEN_REGLA,0)))) | DD8: =IF(K8<>"gasolina","",IFERROR(VLOOKUP(F8,CONS_MOD_TBL,2,0),IFERROR(VLOOKUP(L8,CONS_SEG_TBL,2,0),""))) | DE8: =IF(DD8="",NEUTRO,MAX(0,MIN(100,100*(CONS_REF_MAX-DD8)/(CONS_REF_MAX-CONS_REF_MIN)))) | DF8: =IFERROR(VLOOKUP(L8,SEGURO_TBL,3,0),"") | DG8: =IF(DF8="",NEUTRO,MAX(0,MIN(100,100*(SEG_REF_MAX-DF8)/(SEG_REF_MAX-SEG_REF_MIN)))) | DH8: =IFERROR(VLOOKUP(E8,MANT_MARCA_TBL,2,0)+0,NEUTRO) | DI8: =IF(DA8="",NEUTRO,IFERROR(VLOOKUP(DA8,DIST_PTS_TBL,2,0)+0,NEUTRO)) | DJ8: =(DH8+DI8)/2 | DK8: =W_CONS*DE8+W_SEG*DG8+W_MANT*DJ8 | DL8: =IF(N(AB8)>0,AB8,IF(AND(R8="profesional",SG_LEGAL_ON=1),GAR_LEGAL,0)) | DM8: =MAX(0,MIN(100,SG_GAR*MIN(1,DL8/SG_GAR_FULL)+SG_AMPL*(AC8="sí")+SG_KMC*(AF8="sí")+SG_REV*(N(AE8)>0)+SG_DEV*MIN(1,N(AG8)/SG_DEV_FULL)+SG_HIST*(W8="sí")-IF(AND(R8="particular",DL8=0),SG_PART_PEN,0))) | DN8: =IF(BK8="",NEUTRO,MAX(0,MIN(100,BK8/5*100))) | DO8: =IF(BL8="sí",100,IF(BL8="no",0,NEUTRO)) | DP8: =SV_W_NCAP*DN8+SV_W_ESP*DO8 | DQ8: =MAX(0,MIN(100,ATR_BASE+ATR_ACAB*(BD8<>"")+IF(BE8="16+",ATR_LL16,IF(BE8="sí",ATR_LL,0))+ATR_FAROS*(BF8="sí")+ATR_TINT*(BG8="sí")-ATR_CHAPA*(BE8="chapa"))) | DR8: =EST_W_MOD*(BB8-1)/4*100+EST_W_ATR*DQ8 | DS8: =IF(BA8="",NEUTRO,IFERROR(VLOOKUP(BA8,COLOR_TBL,2,0)+0,NEUTRO)) | DT8: =MAX(0,MIN(100,100*N(BM8)/RV_N_FULL)) | DU8: =IF(OR(BN8="",N(BO8)<RV_DIAS_MIN),NEUTRO,MAX(0,MIN(100,100*(RV_DIAS_CERO-BN8)/(RV_DIAS_CERO-RV_DIAS_FULL)))) | DV8: =RV_W_LIQ*DT8+RV_W_DIAS*DU8+RV_W_ETQ*DC8 | DW8: =IFERROR(VLOOKUP(L8,CARR_PEN_TBL,2,0),0) | DX8: =W_FIAB*CS8+W_PRECIO*CU8+W_KMEDAD*CY8+W_ESTADO*DB8+W_USO*DK8+W_SEGURIDAD*DM8+W_SEGVIAL*DP8+W_ESTETICA*DR8+W_COLOR*DS8+W_REVENTA*DV8-DW8-EG8 | DY8: =IF(N(I8)>0,I8,IFERROR(ROUND(_xlfn.NUMBERVALUE(LEFT(G8,FIND(" ",G8&" ")-1),".")*1000,0),99999)) | DZ8: =IF(R8="profesional",0,IF(O8<CUOTA_VALOR_MAX,IF(BW8>ITP_TRAMO_ALTO,SUMIFS(CF_CUOTA,CF_MAS,ITP_TRAMO_ALTO,CF_CCMIN,"<="&DY8,CF_CCMAX,">="&DY8),IF(BW8>ITP_TRAMO_BAJO,SUMIFS(CF_CUOTA,CF_MAS,ITP_TRAMO_BAJO,CF_CCMIN,"<="&DY8,CF_CCMAX,">="&DY8),O8*ITP_TIPO)),O8*ITP_TIPO)) | EA8: =IF(R8="profesional",N(AK8),0) | EB8: =IF(AND(R8="profesional",ISNUMBER(AK8),AL8="sí"),0,TASA_DGT) | EC8: =INFORME_DGT | ED8: =O8+EA8+DZ8+EB8+EC8 | EE8: =ED8+N(DF8) | EF8: =MAX(0,ED8-TOTAL_MAX) | EG8: =EF8/100*PEN_100 | EH8: =IF(R8="particular",ED8+IF(AND(DA8<>"cadena",X8<>"sí"),RES_CORREA,0)+IF(AND(BJ8<>"sí",BW8>=RES_NEUM_EDAD),RES_NEUM,0),"") | EI8: =IF(ED8<=TOTAL_MAX,"sí",IF(ED8<=TECHO,"negociar","no")) | EJ8: =ROUND(DX8,9) | EK8: =IF(EI8<>"no",SUMPRODUCT(($EI$2:$EI$209<>"no")*($EJ$2:$EJ$209>EJ8))+SUMPRODUCT(($EI$2:EI8<>"no")*($EJ$2:EJ8=EJ8)),"")
